<?xml version="1.0" encoding="utf-8"?>
<!-- This URDF was automatically created by SolidWorks to URDF Exporter! Originally created by Stephen Brawner (brawner@gmail.com)
     Commit Version: 1.6.0-4-g7f85cfe  Build Version: 1.6.7995.38578
     For more information, please see http://wiki.ros.org/sw_urdf_exporter -->
<robot name="myrobot">


  <mujoco>
    <compiler meshdir="/home/cherish/yuquan-note/mujoco-model/meshes" balanceinertia="true" discardvisual="false" />
  </mujoco>




 <link name="world"/>
 <joint name="floating_base" type="floating">
     <origin rpy="0 0 0" xyz="0 0 0"/>
     <parent link="world"/>
     <child link="base_link"/>
 </joint>


  <link name="base_link">
    <inertial>
      <origin xyz="-4.46807509552636E-07 -3.03780031174009E-06 -0.0203695556415421" rpy="0 0 0" />
      <mass value="7.22272430383922" />
      <inertia ixx="0.0954744307414278" ixy="2.28771796641983E-05" ixz="-1.18504025384915E-07" iyy="0.0439545752329199" iyz="-7.15870663478248E-07" izz="0.0562080692014873" />
    </inertial>
    <visual>
      <origin xyz="0 0 0" rpy="0 0 0" />
      <geometry>
        <mesh filename="/home/cherish/yuquan-note/mujoco-model/meshes/base_link.STL" />
      </geometry>
      <material name="">
        <color rgba="0.752941176470588 0.752941176470588 0.752941176470588 1" />
      </material>
    </visual>
    <collision>
      <origin xyz="0 0 0" rpy="0 0 0" />
      <geometry>
        <mesh filename="/home/cherish/yuquan-note/mujoco-model/meshes/base_link.STL" />
      </geometry>
    </collision>
  </link>
  <link name="leg1_Link">
    <inertial>
      <origin xyz="-0.0017952323919647 0.0201686547952831 0.0131344142052371" rpy="0 0 0" />
      <mass value="0.107780286994776" />
      <inertia ixx="0.000160570412456261" ixy="7.02314714146653E-06" ixz="4.57365429116415E-06" iyy="6.02075344701354E-05" iyz="-5.16932895953821E-05" izz="0.000105921587244055" />
    </inertial>
    <visual>
      <origin xyz="0 0 0" rpy="0 0 0" />
      <geometry>
        <mesh filename="/home/cherish/yuquan-note/mujoco-model/meshes/leg1_Link.STL" />
      </geometry>
      <material name="">
        <color rgba="0.776470588235294 0.756862745098039 0.737254901960784 1" />
      </material>
    </visual>
    <collision>
      <origin xyz="0 0 0" rpy="0 0 0" />
      <geometry>
        <mesh filename="/home/cherish/yuquan-note/mujoco-model/meshes/leg1_Link.STL" />
      </geometry>
    </collision>
  </link>
  <joint name="leg1_jonit" type="continuous">
    <origin xyz="-0.1015 0.0499999999999998 0" rpy="0 0 0" />
    <parent link="base_link" />
    <child link="leg1_Link" />
    <axis xyz="-1 0 0" />
  </joint>
  <link name="shank1_Link">
    <inertial>
      <origin xyz="-0.0145730362584171 -0.0843871017339916 -0.0868742129879856" rpy="0 0 0" />
      <mass value="0.179910472206487" />
      <inertia ixx="0.000891296395450373" ixy="-4.64314333408932E-05" ixz="-4.77998905816288E-05" iyy="0.000466964254826396" iyz="-0.000355091294112394" izz="0.000446332909144987" />
    </inertial>
    <visual>
      <origin xyz="0 0 0" rpy="0 0 0" />
      <geometry>
        <mesh filename="/home/cherish/yuquan-note/mujoco-model/meshes/shank1_Link.STL" />
      </geometry>
      <material name="">
        <color rgba="0.776470588235294 0.756862745098039 0.737254901960784 1" />
      </material>
    </visual>
    <collision>
      <origin xyz="0 0 0" rpy="0 0 0" />
      <geometry>
        <mesh filename="/home/cherish/yuquan-note/mujoco-model/meshes/shank1_Link.STL" />
      </geometry>
    </collision>
  </link>
  <joint name="shank1_joint" type="continuous">
    <origin xyz="-0.0161 0.075418 0.049114" rpy="0 0 0" />
    <parent link="leg1_Link" />
    <child link="shank1_Link" />
    <axis xyz="1 0 0" />
  </joint>
  <link name="wheel1_Link">
    <inertial>
      <origin xyz="0.00354162426172294 -2.04324877658297E-16 -2.22044604925031E-16" rpy="0 0 0" />
      <mass value="0.410353278347292" />
      <inertia ixx="0.00104917461619554" ixy="-2.85639796916951E-17" ixz="-3.04502907729282E-17" iyy="0.000555029807719852" iyz="4.11478559118823E-09" izz="0.000555006382870292" />
    </inertial>
    <visual>
      <origin xyz="0 0 0" rpy="0 0 0" />
      <geometry>
        <mesh filename="/home/cherish/yuquan-note/mujoco-model/meshes/wheel1_Link.STL" />
      </geometry>
      <material name="">
        <color rgba="0.776470588235294 0.756862745098039 0.737254901960784 1" />
      </material>
    </visual>
    <collision>
      <origin xyz="0 0 0" rpy="0 0 0" />
      <geometry>
        <mesh filename="/home/cherish/yuquan-note/mujoco-model/meshes/wheel1_Link.STL" />
      </geometry>
    </collision>
  </link>
  <joint name="wheel1_joint" type="continuous">
    <origin xyz="0.004 -0.12542 -0.12911" rpy="0 0 0" />
    <parent link="shank1_Link" />
    <child link="wheel1_Link" />
    <axis xyz="1 0 0" />
  </joint>
  <link name="leg2_Link">
    <inertial>
      <origin xyz="-0.0017952331696216 -0.0201686842808947 0.0131343546263725" rpy="0 0 0" />
      <mass value="0.107780249103117" />
      <inertia ixx="0.000160570374710653" ixy="-7.02313882055019E-06" ixz="4.57367014414127E-06" iyy="6.02073888584599E-05" iyz="5.16932191805976E-05" izz="0.000105921695018239" />
    </inertial>
    <visual>
      <origin xyz="0 0 0" rpy="0 0 0" />
      <geometry>
        <mesh filename="/home/cherish/yuquan-note/mujoco-model/meshes/leg2_Link.STL" />
      </geometry>
      <material name="">
        <color rgba="0.776470588235294 0.756862745098039 0.737254901960784 1" />
      </material>
    </visual>
    <collision>
      <origin xyz="0 0 0" rpy="0 0 0" />
      <geometry>
        <mesh filename="/home/cherish/yuquan-note/mujoco-model/meshes/leg2_Link.STL" />
      </geometry>
    </collision>
  </link>
  <joint name="leg2_joint" type="continuous">
    <origin xyz="-0.1015 -0.05 0" rpy="0 0 0" />
    <parent link="base_link" />
    <child link="leg2_Link" />
    <axis xyz="-1 0 0" />
  </joint>
  <link name="shank2_Link">
    <inertial>
      <origin xyz="-0.0213519530085939 0.0618445749093326 -0.063667298227435" rpy="0 0 0" />
      <mass value="0.110969681386475" />
      <inertia ixx="0.00037579886255165" ixy="6.47426948579346E-05" ixz="-6.66508334419095E-05" iyy="0.000223149504950312" iyz="0.000177630248884272" izz="0.000212828916611607" />
    </inertial>
    <visual>
      <origin xyz="0 0 0" rpy="0 0 0" />
      <geometry>
        <mesh filename="/home/cherish/yuquan-note/mujoco-model/meshes/shank2_Link.STL" />
      </geometry>
      <material name="">
        <color rgba="0.776470588235294 0.756862745098039 0.737254901960784 1" />
      </material>
    </visual>
    <collision>
      <origin xyz="0 0 0" rpy="0 0 0" />
      <geometry>
        <mesh filename="/home/cherish/yuquan-note/mujoco-model/meshes/shank2_Link.STL" />
      </geometry>
    </collision>
  </link>
  <joint name="shank2_joint" type="continuous">
    <origin xyz="-0.0161000000000003 -0.0754176068674125 0.0491139957078696" rpy="0 0 0" />
    <parent link="leg2_Link" />
    <child link="shank2_Link" />
    <axis xyz="-1 0 0" />
  </joint>
  <link name="leg3_Link">
    <inertial>
      <origin xyz="0.00179523239196487 -0.0201686547952831 0.0131344142052372" rpy="0 0 0" />
      <mass value="0.107780286994777" />
      <inertia ixx="0.000160570412456261" ixy="7.02314714146646E-06" ixz="-4.5736542911641E-06" iyy="6.02075344701358E-05" iyz="5.16932895953824E-05" izz="0.000105921587244055" />
    </inertial>
    <visual>
      <origin xyz="0 0 0" rpy="0 0 0" />
      <geometry>
        <mesh filename="/home/cherish/yuquan-note/mujoco-model/meshes/leg3_Link.STL" />
      </geometry>
      <material name="">
        <color rgba="0.776470588235294 0.756862745098039 0.737254901960784 1" />
      </material>
    </visual>
    <collision>
      <origin xyz="0 0 0" rpy="0 0 0" />
      <geometry>
        <mesh filename="/home/cherish/yuquan-note/mujoco-model/meshes/leg3_Link.STL" />
      </geometry>
    </collision>
  </link>
  <joint name="leg3_joint" type="continuous">
    <origin xyz="0.1015 -0.05 0" rpy="0 0 0" />
    <parent link="base_link" />
    <child link="leg3_Link" />
    <axis xyz="1 0 0" />
  </joint>
  <link name="shank3_Link">
    <inertial>
      <origin xyz="0.0145730362584168 0.084387101733991 -0.0868742129879853" rpy="0 0 0" />
      <mass value="0.179910472206486" />
      <inertia ixx="0.000891296395450371" ixy="-4.64314333408934E-05" ixz="4.77998905816297E-05" iyy="0.000466964254826399" iyz="0.000355091294112392" izz="0.000446332909144982" />
    </inertial>
    <visual>
      <origin xyz="0 0 0" rpy="0 0 0" />
      <geometry>
        <mesh filename="/home/cherish/yuquan-note/mujoco-model/meshes/shank3_Link.STL" />
      </geometry>
      <material name="">
        <color rgba="0.776470588235294 0.756862745098039 0.737254901960784 1" />
      </material>
    </visual>
    <collision>
      <origin xyz="0 0 0" rpy="0 0 0" />
      <geometry>
        <mesh filename="/home/cherish/yuquan-note/mujoco-model/meshes/shank3_Link.STL" />
      </geometry>
    </collision>
  </link>
  <joint name="shank3_joint" type="continuous">
    <origin xyz="0.0161 -0.075418 0.049114" rpy="0 0 0" />
    <parent link="leg3_Link" />
    <child link="shank3_Link" />
    <axis xyz="-1 0 0" />
  </joint>
  <link name="wheel2_Link">
    <inertial>
      <origin xyz="-0.00354162426172289 2.8655932829755E-15 1.36002320516582E-15" rpy="0 0 0" />
      <mass value="0.410353278347292" />
      <inertia ixx="0.00104917461619554" ixy="4.6378984619299E-19" ixz="6.77337775593484E-19" iyy="0.000555019144316728" iyz="-1.23697982303607E-08" izz="0.000555017046273415" />
    </inertial>
    <visual>
      <origin xyz="0 0 0" rpy="0 0 0" />
      <geometry>
        <mesh filename="/home/cherish/yuquan-note/mujoco-model/meshes/wheel2_Link.STL" />
      </geometry>
      <material name="">
        <color rgba="0.776470588235294 0.756862745098039 0.737254901960784 1" />
      </material>
    </visual>
    <collision>
      <origin xyz="0 0 0" rpy="0 0 0" />
      <geometry>
        <mesh filename="/home/cherish/yuquan-note/mujoco-model/meshes/wheel2_Link.STL" />
      </geometry>
    </collision>
  </link>
  <joint name="wheel2_joint" type="continuous">
    <origin xyz="-0.004 0.12542 -0.12911" rpy="0 0 0" />
    <parent link="shank3_Link" />
    <child link="wheel2_Link" />
    <axis xyz="-1 0 0" />
  </joint>
  <link name="leg4_Link">
    <inertial>
      <origin xyz="0.00179523316962174 -0.0201686842808948 -0.0131343546263721" rpy="0 0 0" />
      <mass value="0.107780249103117" />
      <inertia ixx="0.000160570374710654" ixy="7.02313882055005E-06" ixz="4.5736701441411E-06" iyy="6.02073888584595E-05" iyz="-5.16932191805974E-05" izz="0.000105921695018239" />
    </inertial>
    <visual>
      <origin xyz="0 0 0" rpy="0 0 0" />
      <geometry>
        <mesh filename="/home/cherish/yuquan-note/mujoco-model/meshes/leg4_Link.STL" />
      </geometry>
      <material name="">
        <color rgba="0.776470588235294 0.756862745098039 0.737254901960784 1" />
      </material>
    </visual>
    <collision>
      <origin xyz="0 0 0" rpy="0 0 0" />
      <geometry>
        <mesh filename="/home/cherish/yuquan-note/mujoco-model/meshes/leg4_Link.STL" />
      </geometry>
    </collision>
  </link>
  <joint name="leg4_joint" type="continuous">
    <origin xyz="0.1015 0.05 0" rpy="3.1416 0 0" />
    <parent link="base_link" />
    <child link="leg4_Link" />
    <axis xyz="1 0 0" />
  </joint>
  <link name="shank4_Link">
    <inertial>
      <origin xyz="0.0213519530085934 -0.0618445749093328 -0.063667298227434" rpy="0 0 0" />
      <mass value="0.110969681386475" />
      <inertia ixx="0.000375798862551648" ixy="6.47426948579352E-05" ixz="6.66508334419093E-05" iyy="0.00022314950495031" iyz="-0.000177630248884271" izz="0.000212828916611609" />
    </inertial>
    <visual>
      <origin xyz="0 0 0" rpy="0 0 0" />
      <geometry>
        <mesh filename="/home/cherish/yuquan-note/mujoco-model/meshes/shank4_Link.STL" />
      </geometry>
      <material name="">
        <color rgba="0.776470588235294 0.756862745098039 0.737254901960784 1" />
      </material>
    </visual>
    <collision>
      <origin xyz="0 0 0" rpy="0 0 0" />
      <geometry>
        <mesh filename="/home/cherish/yuquan-note/mujoco-model/meshes/shank4_Link.STL" />
      </geometry>
    </collision>
  </link>
  <joint name="shank4_joint" type="continuous">
    <origin xyz="0.0161 -0.075418 -0.049114" rpy="3.1416 0 0" />
    <parent link="leg4_Link" />
    <child link="shank4_Link" />
    <axis xyz="1 0 0" />
  </joint>
  <link name="wheel3_Link">
    <inertial>
      <origin xyz="-2.77555756156289E-17 4.36088455364593E-17 2.02761771147199E-16" rpy="0 0 0" />
      <mass value="0.0632598262485195" />
      <inertia ixx="0.00242059945488792" ixy="-2.39877532612219E-19" ixz="-2.14203771470045E-18" iyy="0.00121214011620725" iyz="1.71947688292624E-19" izz="0.00121214011620725" />
    </inertial>
    <visual>
      <origin xyz="0 0 0" rpy="0 0 0" />
      <geometry>
        <mesh filename="/home/cherish/yuquan-note/mujoco-model/meshes/wheel3_Link.STL" />
      </geometry>
      <material name="">
        <color rgba="0.298039215686275 0.298039215686275 0.298039215686275 1" />
      </material>
    </visual>
    <collision>
      <origin xyz="0 0 0" rpy="0 0 0" />
      <geometry>
        <mesh filename="/home/cherish/yuquan-note/mujoco-model/meshes/wheel3_Link.STL" />
      </geometry>
    </collision>
  </link>
  <joint name="wheel3_joint" type="continuous">
    <origin xyz="-0.068 0 0" rpy="0 0 0" />
    <parent link="base_link" />
    <child link="wheel3_Link" />
    <axis xyz="0.97803 -0.14849 0.14631" />
  </joint>
  <link name="wheel4_Link">
    <inertial>
      <origin xyz="3.46944695195361E-16 3.88965656475174E-17 -1.09251345945501E-16" rpy="0 0 0" />
      <mass value="0.0632598262485197" />
      <inertia ixx="0.00242059945488793" ixy="-4.83254489522524E-19" ixz="1.04694715430991E-19" iyy="0.00121214011620725" iyz="2.13134665352864E-20" izz="0.00121214011620725" />
    </inertial>
    <visual>
      <origin xyz="0 0 0" rpy="0 0 0" />
      <geometry>
        <mesh filename="/home/cherish/yuquan-note/mujoco-model/meshes/wheel4_Link.STL" />
      </geometry>
      <material name="">
        <color rgba="0.298039215686275 0.298039215686275 0.298039215686275 1" />
      </material>
    </visual>
    <collision>
      <origin xyz="0 0 0" rpy="0 0 0" />
      <geometry>
        <mesh filename="/home/cherish/yuquan-note/mujoco-model/meshes/wheel4_Link.STL" />
      </geometry>
    </collision>
  </link>
  <joint name="wheel4_joint" type="continuous">
    <origin xyz="0.068 0 0" rpy="3.1416 0 0" />
    <parent link="base_link" />
    <child link="wheel4_Link" />
    <axis xyz="0.97803 0.14849 -0.14631" />
  </joint>
</robot>

